Workbook

Sheet 25%
A1: calendar_year | B1: population_alive | C1: entrants | D1: deaths | E1: incident_onsets | F1: incidence_per_1000_alive | G1: total_qalys_patient | H1: total_qalys_caregiver | I1: total_qalys_total | J1: total_costs_nhs | K1: total_costs_informal | L1: total_costs_nhs_perspective | M1: total_costs_societal | N1: dementia_cases_total | O1: mean_age_alive | P1: mean_age_dementia | Q1: stage_cognitively_normal | R1: stage_mild | S1: stage_moderate | T1: stage_severe | U1: stage_death | V1: living_home | W1: living_institution | X1: year_qalys_patient | Y1: year_qalys_caregiver | Z1: year_qalys_total | AA1: year_costs_nhs | AB1: year_costs_informal | AC1: year_costs_societal
A2: 2023 | B2: 10787479 | C2: 700000 | D2: 490000 | E2: 80000 | F2: 7.4160052 | G2: 0 | H2: 0 | I2: 0 | J2: 0 | K2: 0 | L2: 0 | M2: 0 | N2: 802386 | O2: 80.979452 | P2: 87.567468 | Q2: 9985093 | R2: 398969 | S2: 299115 | T2: 104302 | U2: 0 | V2: 10787479 | W2: 0 | X2: 0 | Y2: 0 | Z2: 0 | AA2: 0 | AB2: 0 | AC2: 0
A3: 2024 | B3: 10999650 | C3: 704136 | D3: 493478 | E3: 89927 | F3: 8.1754419 | G3: 7978152.1 | H3: 627985.8 | I3: 8606137.9 | J3: 8.3271702e+09 | K3: 1.7493522e+10 | L3: 8.3271702e+09 | M3: 2.5820692e+10 | N3: 819061 | O3: 81.515766 | P3: 87.975036 | Q3: 10180589 | R3: 326967 | S3: 315087 | T3: 193971 | U3: 475001 | V3: 10901571 | W3: 98079 | X3: 7978152.1 | Y3: 627985.8 | Z3: 8606137.9 | AA3: 8.3271702e+09 | AB3: 1.7493522e+10 | AC3: 2.5820692e+10 | AD3: =AC3/N3 -> 31524.749
A4: 2025 | B4: 11193863 | C4: 708297 | D4: 516817 | E4: 93521 | F4: 8.3546672 | G4: 15796085 | H4: 1178070.7 | I4: 16974156 | J4: 1.9087517e+10 | K4: 3.3355692e+10 | L4: 1.9087517e+10 | M4: 5.2443209e+10 | N4: 820669 | O4: 82.01403 | P4: 88.326708 | Q4: 10373194 | R4: 287365 | S4: 302457 | T4: 263420 | U4: 973476 | V4: 11017151 | W4: 176712 | X4: 7817933.1 | Y4: 550084.92 | Z4: 8368018 | AA4: 1.0760347e+10 | AB4: 1.586217e+10 | AC4: 2.6622517e+10
A5: 2026 | B5: 11366854 | C5: 712482 | D5: 543200 | E5: 96848 | F5: 8.5202115 | G5: 23450427 | H5: 1661264.4 | I5: 25111691 | J5: 3.1752058e+10 | K5: 4.734794e+10 | L5: 3.1752058e+10 | M5: 7.9099998e+10 | N5: 812023 | O5: 82.481883 | P5: 88.621279 | Q5: 10554831 | R5: 267465 | S5: 282885 | T5: 308662 | U5: 1498551 | V5: 11134832 | W5: 232022 | X5: 7654341.3 | Y5: 483193.65 | Z5: 8137535 | AA5: 1.2664541e+10 | AB5: 1.3992248e+10 | AC5: 2.6656789e+10
A6: 2027 | B6: 11523013 | C6: 716692 | D6: 564869 | E6: 100015 | F6: 8.6795875 | G6: 30937455 | H6: 2090715.5 | I6: 33028170 | J6: 4.5564808e+10 | K6: 5.9651271e+10 | L6: 4.5564808e+10 | M6: 1.0521608e+11 | N6: 797454 | O6: 82.925729 | P6: 88.871663 | Q6: 10725559 | R6: 258611 | S6: 268013 | T6: 331118 | U6: 2045785 | V6: 11256498 | W6: 266515 | X6: 7487028.2 | Y6: 429451.13 | Z6: 7916479.3 | AA6: 1.381275e+10 | AB6: 1.2303332e+10 | AC6: 2.6116082e+10
A7: 2028 | B7: 11675456 | C7: 720927 | D7: 573190 | E7: 103905 | F7: 8.8994383 | G7: 38255910 | H7: 2479332 | I7: 40735242 | J7: 5.9855957e+10 | K7: 7.0572595e+10 | L7: 5.9855957e+10 | M7: 1.3042855e+11 | N7: 784582 | O7: 83.361713 | P7: 89.079384 | Q7: 10890874 | R7: 257312 | S7: 258699 | T7: 341452 | U7: 2601676 | V7: 11389320 | W7: 286136 | X7: 7318455.6 | Y7: 388616.55 | Z7: 7707072.1 | AA7: 1.4291149e+10 | AB7: 1.0921323e+10 | AC7: 2.5212472e+10
A8: 2029 | B8: 11821714 | C8: 725187 | D8: 583559 | E8: 107130 | F8: 9.0621377 | G8: 45406915 | H8: 2838753 | I8: 48245668 | J8: 7.4176863e+10 | K8: 8.0475671e+10 | L8: 7.4176863e+10 | M8: 1.5465253e+11 | N8: 775496 | O8: 83.784676 | P8: 89.288519 | Q8: 11046218 | R8: 259847 | S8: 255954 | T8: 344752 | U8: 3168429 | V8: 11525015 | W8: 296699 | X8: 7151004.6 | Y8: 359420.94 | Z8: 7510425.5 | AA8: 1.4320906e+10 | AB8: 9.9030764e+09 | AC8: 2.4223982e+10
A9: 2030 | B9: 11963962 | C9: 729472 | D9: 592062 | E9: 110093 | F9: 9.202052 | G9: 52390435 | H9: 3177500.4 | I9: 55567935 | J9: 8.8260308e+10 | K9: 8.9645535e+10 | L9: 8.8260308e+10 | M9: 1.7790584e+11 | N9: 770800 | O9: 84.197968 | P9: 89.490551 | Q9: 11193162 | R9: 264382 | S9: 257940 | T9: 345382 | U9: 3743806 | V9: 11662193 | W9: 301769 | X9: 6983519.7 | Y9: 338747.45 | Z9: 7322267.2 | AA9: 1.4083445e+10 | AB9: 9.1698635e+09 | AC9: 2.3253308e+10
A10: 2031 | B10: 12106904 | C10: 733782 | D10: 595526 | E10: 113417 | F10: 9.3679606 | G10: 59208343 | H10: 3502202.7 | I10: 62710545 | J10: 1.0197195e+11 | K10: 9.8305377e+10 | L10: 1.0197195e+11 | M10: 2.0027733e+11 | N10: 771674 | O10: 84.613053 | P10: 89.690063 | Q10: 11335230 | R10: 270956 | S10: 263594 | T10: 345790 | U10: 4322884 | V10: 11802553 | W10: 304351 | X10: 6817908 | Y10: 324702.24 | Z10: 7142610.3 | AA10: 1.3711647e+10 | AB10: 8.6598423e+09 | AC10: 2.2371489e+10
A11: 2032 | B11: 12250228 | C11: 738118 | D11: 599361 | E11: 117696 | F11: 9.6076579 | G11: 65862843 | H11: 3818267.6 | I11: 69681110 | J11: 1.1529142e+11 | K11: 1.0664903e+11 | L11: 1.1529142e+11 | M11: 2.2194045e+11 | N11: 778566 | O11: 85.028942 | P11: 89.920431 | Q11: 11471662 | R11: 278852 | S11: 272499 | T11: 347263 | U11: 4906296 | V11: 11944307 | W11: 305921 | X11: 6654500.1 | Y11: 316064.89 | Z11: 6970565 | AA11: 1.3319469e+10 | AB11: 8.3436538e+09 | AC11: 2.1663123e+10
A12: 2033 | B12: 12393973 | C12: 742479 | D12: 603026 | E12: 121014 | F12: 9.7639393 | G12: 72356393 | H12: 4128393.7 | I12: 76484787 | J12: 1.2826543e+11 | K12: 1.1477991e+11 | L12: 1.2826543e+11 | M12: 2.4304535e+11 | N12: 789791 | O12: 85.444474 | P12: 90.181658 | Q12: 11604182 | R12: 286977 | S12: 282897 | T12: 351478 | U12: 5493517 | V12: 12085012 | W12: 308961 | X12: 6493550.5 | Y12: 310126.12 | Z12: 6803676.6 | AA12: 1.297401e+10 | AB12: 8.1308827e+09 | AC12: 2.1104893e+10
A13: 2034 | B13: 12539717 | C13: 746867 | D13: 605395 | E13: 124254 | F13: 9.9088361 | G13: 78702605 | H13: 4434258.3 | I13: 83136864 | J13: 1.4094494e+11 | K13: 1.2276635e+11 | L13: 1.4094494e+11 | M13: 2.6371128e+11 | N13: 805230 | O13: 85.85913 | P13: 90.47748 | Q13: 11734487 | R13: 295404 | S13: 294279 | T13: 358388 | U13: 6083360 | V13: 12226369 | W13: 313348 | X13: 6346212.1 | Y13: 305864.63 | Z13: 6652076.8 | AA13: 1.2679505e+10 | AB13: 7.9864326e+09 | AC13: 2.0665937e+10
A14: 2035 | B14: 12680808 | C14: 751280 | D14: 614388 | E14: 128743 | F14: 10.152586 | G14: 84902808 | H14: 4737477.2 | I14: 89640286 | J14: 1.533933e+11 | K14: 1.3065342e+11 | L14: 1.533933e+11 | M14: 2.8404672e+11 | N14: 824068 | O14: 86.267273 | P14: 90.801522 | Q14: 11856740 | R14: 305018 | S14: 306981 | T14: 366966 | U14: 6681493 | V14: 12362135 | W14: 318673 | X14: 6200203.1 | Y14: 303218.89 | Z14: 6503422 | AA14: 1.2448364e+10 | AB14: 7.8870726e+09 | AC14: 2.0335436e+10
A15: 2036 | B15: 12819768 | C15: 755719 | D15: 620843 | E15: 131111 | F15: 10.227252 | G15: 90957709 | H15: 5038123 | I15: 95995832 | J15: 1.6563645e+11 | K15: 1.3847736e+11 | L15: 1.6563645e+11 | M15: 3.041138e+11 | N15: 844382 | O15: 86.666755 | P15: 91.150049 | Q15: 11975386 | R15: 313008 | S15: 321092 | T15: 377220 | U15: 7286211 | V15: 12494517 | W15: 325251 | X15: 6054900.1 | Y15: 300645.83 | Z15: 6355545.9 | AA15: 1.2243147e+10 | AB15: 7.8239363e+09 | AC15: 2.0067083e+10
... A19: 2040 | B19: 13348127 | C19: 773740 | D19: 686798 | E19: 146962 | F19: 11.009934 | G19: 1.1382257e+08 | H19: 6231079.5 | I19: 1.2005365e+08 | J19: 2.138749e+11 | K19: 1.6951621e+11 | L19: 2.138749e+11 | M19: 3.833911e+11 | N19: 946903 | O19: 88.195408 | P19: 92.848417 | Q19: 12401224 | R19: 351774 | S19: 378415 | T19: 433464 | U19: 9775835 | V19: 12984245 | W19: 363882 | X19: 5492715.8 | Y19: 294436.62 | Z19: 5787152.5 | AA19: 1.1877562e+10 | AB19: 7.6619651e+09 | AC19: 1.9539527e+10
E20: =(E19-E3)/E3 -> 0.63423666 | N20: =(N19-N3)/N3 -> 0.15608361 | O20: =AVERAGE(O2:O19) -> 84.772422

Sheet 50%
A1: calendar_year | B1: population_alive | C1: entrants | D1: deaths | E1: incident_onsets | F1: incidence_per_1000_alive | G1: total_qalys_patient | H1: total_qalys_caregiver | I1: total_qalys_total | J1: total_costs_nhs | K1: total_costs_informal | L1: total_costs_nhs_perspective | M1: total_costs_societal | N1: dementia_cases_total | O1: mean_age_alive | P1: mean_age_dementia | Q1: stage_cognitively_normal | R1: stage_mild | S1: stage_moderate | T1: stage_severe | U1: stage_death | V1: living_home | W1: living_institution | X1: year_qalys_patient | Y1: year_qalys_caregiver | Z1: year_qalys_total | AA1: year_costs_nhs | AB1: year_costs_informal | AC1: year_costs_societal
A2: 2023 | B2: 10787479 | C2: 700000 | D2: 490000 | E2: 80000 | F2: 7.4160052 | G2: 0 | H2: 0 | I2: 0 | J2: 0 | K2: 0 | L2: 0 | M2: 0 | N2: 802386 | O2: 80.979452 | P2: 87.567468 | Q2: 9985093 | R2: 398969 | S2: 299115 | T2: 104302 | U2: 0 | V2: 10787479 | W2: 0 | X2: 0 | Y2: 0 | Z2: 0 | AA2: 0 | AB2: 0 | AC2: 0
A3: 2024 | B3: 10999835 | C3: 704136 | D3: 493275 | E3: 99736 | F3: 9.0670451 | G3: 7978474.5 | H3: 635408.26 | I3: 8613882.8 | J3: 8.4190733e+09 | K3: 1.7581427e+10 | L3: 8.4190733e+09 | M3: 2.60005e+10 | N3: 829284 | O3: 81.516015 | P3: 87.960729 | Q3: 10170551 | R3: 336552 | S3: 315882 | T3: 193628 | U3: 475002 | V3: 10900643 | W3: 99192 | X3: 7978474.5 | Y3: 635408.26 | Z3: 8613882.8 | AA3: 8.4190733e+09 | AB3: 1.7581427e+10 | AC3: 2.60005e+10
A4: 2025 | B4: 11193705 | C4: 708297 | D4: 517058 | E4: 103161 | F4: 9.2159834 | G4: 15795940 | H4: 1199842.3 | I4: 16995783 | J4: 1.9333485e+10 | K4: 3.3690358e+10 | L4: 1.9333485e+10 | M4: 5.3023843e+10 | N4: 840022 | O4: 82.013938 | P4: 88.297718 | Q4: 10353683 | R4: 302751 | S4: 306866 | T4: 262942 | U4: 973670 | V4: 11015182 | W4: 178523 | X4: 7817465.7 | Y4: 564434.04 | Z4: 8381899.8 | AA4: 1.0914411e+10 | AB4: 1.6108931e+10 | AC4: 2.7023343e+10
A5: 2026 | B5: 11366733 | C5: 712482 | D5: 543198 | E5: 106448 | F5: 9.364872 | G5: 23448978 | H5: 1701303.1 | I5: 25150281 | J5: 3.2252806e+10 | K5: 4.8044977e+10 | L5: 3.2252806e+10 | M5: 8.0297783e+10 | N5: 839514 | O5: 82.482078 | P5: 88.575961 | Q5: 10527219 | R5: 286033 | S5: 291594 | T5: 309128 | U5: 1498420 | V5: 11130360 | W5: 236373 | X5: 7653038.1 | Y5: 501460.82 | Z5: 8154498.9 | AA5: 1.2919322e+10 | AB5: 1.4354618e+10 | AC5: 2.727394e+10
A6: 2027 | B6: 11525000 | C6: 716692 | D6: 562724 | E6: 110430 | F6: 9.5817787 | G6: 30933944 | H6: 2152619.4 | I6: 33086564 | J6: 4.6432683e+10 | K6: 6.0818166e+10 | L6: 4.6432683e+10 | M6: 1.0725085e+11 | N6: 834254 | O6: 82.92848 | P6: 88.806824 | Q6: 10690746 | R6: 279925 | S6: 280461 | T6: 334918 | U6: 2043036 | V6: 11250866 | W6: 274134 | X6: 7484966.1 | Y6: 451316.27 | Z6: 7936282.4 | AA6: 1.4179877e+10 | AB6: 1.277319e+10 | AC6: 2.6953066e+10
A7: 2028 | B7: 11675527 | C7: 720927 | D7: 575162 | E7: 114157 | F7: 9.7774602 | G7: 38249033 | H7: 2566012.4 | I7: 40815045 | J7: 6.1233057e+10 | K7: 7.2310321e+10 | L7: 6.1233057e+10 | M7: 1.3354338e+11 | N7: 829460 | O7: 83.363695 | P7: 89.011914 | Q7: 10846067 | R7: 280248 | S7: 274760 | T7: 348830 | U7: 2600108 | V7: 11377906 | W7: 297621 | X7: 7315088.5 | Y7: 413392.99 | Z7: 7728481.4 | AA7: 1.4800373e+10 | AB7: 1.1492155e+10 | AC7: 2.6292528e+10
A8: 2029 | B8: 11821575 | C8: 725187 | D8: 584097 | E8: 117661 | F8: 9.9530731 | G8: 45395103 | H8: 2951827.7 | I8: 48346930 | J8: 7.6215412e+10 | K8: 8.283884e+10 | L8: 7.6215412e+10 | M8: 1.5905425e+11 | N8: 827036 | O8: 83.786842 | P8: 89.202899 | Q8: 10994539 | R8: 284269 | S8: 274061 | T8: 355968 | U8: 3166363 | V8: 11510078 | W8: 311497 | X8: 7146069.8 | Y8: 385815.27 | Z8: 7531885.1 | AA8: 1.4982355e+10 | AB8: 1.052852e+10 | AC8: 2.5510875e+10
A9: 2030 | B9: 11962164 | C9: 729472 | D9: 593814 | E9: 121290 | F9: 10.13947 | G9: 52372599 | H9: 3318424.2 | I9: 55691024 | J9: 9.1070447e+10 | K9: 9.2694156e+10 | L9: 9.1070447e+10 | M9: 1.837646e+11 | N9: 828032 | O9: 84.200196 | P9: 89.400728 | Q9: 11134132 | R9: 290026 | S9: 278459 | T9: 359425 | U9: 3742630 | V9: 11642948 | W9: 319216 | X9: 6977496.7 | Y9: 366596.58 | Z9: 7344093.3 | AA9: 1.4855035e+10 | AB9: 9.8553153e+09 | AC9: 2.471035e+10
A10: 2031 | B10: 12101044 | C10: 733782 | D10: 599759 | E10: 124237 | F10: 10.266635 | G10: 59181721 | H10: 3671666.3 | I10: 62853387 | J10: 1.0563379e+11 | K10: 1.0207741e+11 | L10: 1.0563379e+11 | M10: 2.077112e+11 | N10: 832790 | O10: 84.61295 | P10: 89.603417 | Q10: 11268254 | R10: 296547 | S10: 285881 | T10: 362852 | U10: 4324920 | V10: 11777322 | W10: 323722 | X10: 6809121.4 | Y10: 353242.05 | Z10: 7162363.4 | AA10: 1.456334e+10 | AB10: 9.3832546e+09 | AC10: 2.3946595e+10
A11: 2032 | B11: 12242273 | C11: 738118 | D11: 601514 | E11: 128443 | F11: 10.491761 | G11: 65825631 | H11: 4015980.8 | I11: 69841611 | J11: 1.198805e+11 | K11: 1.1114149e+11 | L11: 1.198805e+11 | M11: 2.3102199e+11 | N11: 843482 | O11: 85.029413 | P11: 89.852905 | Q11: 11398791 | R11: 304872 | S11: 295432 | T11: 368222 | U11: 4909255 | V11: 11913749 | W11: 328524 | X11: 6643909.9 | Y11: 344314.47 | Z11: 6988224.4 | AA11: 1.4246711e+10 | AB11: 9.0640805e+09 | AC11: 2.3310792e+10
A12: 2033 | B12: 12381253 | C12: 742479 | D12: 608195 | E12: 132729 | F12: 10.720159 | G12: 72306484 | H12: 4354234.4 | I12: 76660719 | J12: 1.3384207e+11 | K12: 1.1998966e+11 | L12: 1.3384207e+11 | M12: 2.5383174e+11 | N12: 858485 | O12: 85.442476 | P12: 90.122725 | Q12: 11522768 | R12: 314130 | S12: 307310 | T12: 374682 | U12: 5500161 | V12: 12047786 | W12: 333467 | X12: 6480853.6 | Y12: 338253.65 | Z12: 6819107.3 | AA12: 1.3961573e+10 | AB12: 8.848173e+09 | AC12: 2.2809746e+10
A13: 2034 | B13: 12521219 | C13: 746867 | D13: 611326 | E13: 135796 | F13: 10.84527 | G13: 78637837 | H13: 4688605.8 | I13: 83326443 | J13: 1.4752574e+11 | K13: 1.2871428e+11 | L13: 1.4752574e+11 | M13: 2.7624003e+11 | N13: 876577 | O13: 85.853939 | P13: 90.422367 | Q13: 11644642 | R13: 323203 | S13: 320362 | T13: 383140 | U13: 6094571 | V13: 12182597 | W13: 338622 | X13: 6331352.8 | Y13: 334371.38 | Z13: 6665724.1 | AA13: 1.3683673e+10 | AB13: 8.7246168e+09 | AC13: 2.2408289e+10
... A19: 2040 | B19: 13306219 | C19: 773740 | D19: 691269 | E19: 159591 | F19: 11.993715 | G19: 1.136319e+08 | H19: 6654336.4 | I19: 1.2028623e+08 | J19: 2.2676557e+11 | K19: 1.7990158e+11 | L19: 2.2676557e+11 | M19: 4.0666716e+11 | N19: 1033451 | O19: 88.177632 | P19: 92.793336 | Q19: 12272768 | R19: 382830 | S19: 412669 | T19: 468553 | U19: 9803892 | V19: 12909231 | W19: 396988 | X19: 5469130.1 | Y19: 321708.7 | Z19: 5790838.8 | AA19: 1.2934465e+10 | AB19: 8.3948153e+09 | AC19: 2.132928e+10
E20: =(E19-E3)/E3 -> 0.60013435 | N20: =(N19-N3)/N3 -> 0.24619672 | O20: =AVERAGE(O2:O19) -> 84.768592

Sheet 75%
A1: calendar_year | B1: population_alive | C1: entrants | D1: deaths | E1: incident_onsets | G1: incidence_per_1000_alive | H1: total_qalys_patient | I1: total_qalys_caregiver | J1: total_qalys_total | K1: total_costs_nhs | L1: total_costs_informal | M1: total_costs_nhs_perspective | N1: total_costs_societal | O1: dementia_cases_total | P1: mean_age_alive | Q1: mean_age_dementia | R1: stage_cognitively_normal | S1: stage_mild | T1: stage_moderate | U1: stage_severe | V1: stage_death | W1: living_home | X1: living_institution | Y1: year_qalys_patient | Z1: year_qalys_caregiver | AA1: year_qalys_total | AB1: year_costs_nhs | AC1: year_costs_informal | AD1: year_costs_societal
A2: 2023 | B2: 10787479 | C2: 700000 | D2: 490000 | E2: 80000 | G2: 7.4160052 | H2: 0 | I2: 0 | J2: 0 | K2: 0 | L2: 0 | M2: 0 | N2: 0 | O2: 802386 | P2: 80.979452 | Q2: 87.567468 | R2: 9985093 | S2: 398969 | T2: 299115 | U2: 104302 | V2: 0 | W2: 10787479 | X2: 0 | Y2: 0 | Z2: 0 | AA2: 0 | AB2: 0 | AC2: 0 | AD2: 0
A3: 2024 | B3: 10999428 | C3: 704136 | D3: 493667 | E3: 108478 | F3: =(E3-E2)/E2 -> 0.355975 | G3: 9.8621492 | H3: 7977430.4 | I3: 641542.58 | J3: 8618972.9 | K3: 8.5049194e+09 | L3: 1.7651837e+10 | M3: 8.5049194e+09 | N3: 2.6156757e+10 | O3: 838038 | P3: 81.515922 | Q3: 87.948286 | R3: 10161390 | S3: 344907 | T3: 315859 | U3: 194027 | V3: 475432 | W3: 10898995 | X3: 100433 | Y3: 7977430.4 | Z3: 641542.58 | AA3: 8618972.9 | AB3: 8.5049194e+09 | AC3: 1.7651837e+10 | AD3: 2.6156757e+10 | AE3: =(AD3-AD2)/AD2 -> #DIV/0!
A4: 2025 | B4: 11192996 | C4: 708297 | D4: 517382 | E4: 112992 | F4: =(E4-E3)/E3 -> 0.041612124 | G4: 10.094884 | H4: 15793913 | I4: 1218113.5 | J4: 17012027 | K4: 1.9596855e+10 | L4: 3.3940121e+10 | M4: 1.9596855e+10 | N4: 5.3536976e+10 | O4: 857889 | P4: 82.013832 | Q4: 88.26773 | R4: 10335107 | S4: 317577 | T4: 309318 | U4: 263902 | V4: 974008 | W4: 11011275 | X4: 181721 | Y4: 7816483 | Z4: 576570.96 | AA4: 8393053.9 | AB4: 1.1091936e+10 | AC4: 1.6288283e+10 | AD4: 2.7380219e+10 | AE4: =(AD4-AD3)/AD3 -> 0.046774225
A5: 2026 | B5: 11363823 | C5: 712482 | D5: 545342 | E5: 116715 | F5: =(E5-E4)/E4 -> 0.032949235 | G5: 10.270751 | H5: 23444576 | I5: 1737435.4 | J5: 25182011 | K5: 3.2765082e+10 | L5: 4.8627906e+10 | M5: 3.2765082e+10 | N5: 8.1392988e+10 | O5: 866051 | P5: 82.479418 | Q5: 88.528649 | R5: 10497772 | S5: 305083 | T5: 298605 | U5: 310727 | V5: 1500207 | W5: 11123109 | X5: 240714 | Y5: 7650662.3 | Z5: 519321.86 | AA5: 8169984.1 | AB5: 1.3168227e+10 | AC5: 1.4687785e+10 | AD5: 2.7856012e+10 | AE5: =(AD5-AD4)/AD4 -> 0.017377252
A6: 2027 | B6: 11522696 | C6: 716692 | D6: 562308 | E6: 120771 | F6: =(E6-E5)/E5 -> 0.034751317 | G6: 10.481141 | H6: 30925656 | I6: 2210560.1 | J6: 33136216 | K6: 4.7287266e+10 | L6: 6.1856623e+10 | M6: 4.7287266e+10 | N6: 1.0914389e+11 | O6: 868945 | P6: 82.926321 | Q6: 88.750998 | R6: 10653751 | S6: 301902 | T6: 290833 | U6: 338946 | V6: 2043654 | W6: 11242198 | X6: 280498 | Y6: 7481080.6 | Z6: 473124.71 | AA6: 7954205.3 | AB6: 1.4522184e+10 | AC6: 1.3228717e+10 | AD6: 2.7750901e+10 | AE6: =(AD6-AD5)/AD5 -> -0.0037733501
A7: 2028 | B7: 11672117 | C7: 720927 | D7: 576337 | E7: 124164 | F7: =(E7-E6)/E6 -> 0.028094493 | G7: 10.637659 | H7: 38235921 | I7: 2648237.2 | J7: 40884158 | K7: 6.2530521e+10 | L7: 7.3908757e+10 | M7: 6.2530521e+10 | N7: 1.3643928e+11 | O7: 870666 | P7: 83.36003 | Q7: 88.949148 | R7: 10801451 | S7: 302951 | T7: 288722 | U7: 356124 | V7: 2600765 | W7: 11365662 | X7: 306455 | Y7: 7310264.8 | Z7: 437677.1 | AA7: 7747941.9 | AB7: 1.5243255e+10 | AC7: 1.2052134e+10 | AD7: 2.7295389e+10 | AE7: =(AD7-AD6)/AD6 -> -0.016414329
A8: 2029 | B8: 11815484 | C8: 725187 | D8: 586781 | E8: 128342 | F8: =(E8-E7)/E7 -> 0.033649045 | G8: 10.862187 | H8: 45375139 | I8: 3060334.2 | J8: 48435473 | K8: 7.8045113e+10 | L8: 8.507158e+10 | M8: 7.8045113e+10 | N8: 1.6311669e+11 | O8: 874531 | P8: 83.782045 | Q8: 89.141244 | R8: 10940953 | S8: 308143 | T8: 291135 | U8: 366175 | V8: 3168794 | W8: 11492236 | X8: 323248 | Y8: 7139217.9 | Z8: 412097.05 | AA8: 7551314.9 | AB8: 1.5514592e+10 | AC8: 1.1162823e+10 | AD8: 2.6677415e+10 | AE8: =(AD8-AD7)/AD7 -> -0.022640224
A9: 2030 | B9: 11954872 | C9: 729472 | D9: 595085 | E9: 131694 | F9: =(E9-E8)/E8 -> 0.026117717 | G9: 11.015927 | H9: 52343584 | I9: 3454148.6 | J9: 55797732 | K9: 9.3539724e+10 | L9: 9.5598797e+10 | M9: 9.3539724e+10 | N9: 1.8913852e+11 | O9: 881376 | P9: 84.193898 | Q9: 89.335818 | R9: 11073496 | S9: 314612 | T9: 297483 | U9: 373774 | V9: 3745307 | W9: 11620786 | X9: 334086 | Y9: 6968444.7 | Z9: 393814.4 | AA9: 7362259.1 | AB9: 1.5494611e+10 | AC9: 1.0527217e+10 | AD9: 2.6021828e+10 | AE9: =(AD9-AD8)/AD8 -> -0.024574611
A10: 2031 | B10: 12091594 | C10: 733782 | D10: 602031 | E10: 135689 | F10: =(E10-E9)/E9 -> 0.030335475 | G10: 11.221763 | H10: 59142496 | I10: 3835453.3 | J10: 62977949 | K10: 1.0886808e+11 | L10: 1.0568637e+11 | M10: 1.0886808e+11 | N10: 2.1455446e+11 | O10: 892071 | P10: 84.606613 | Q10: 89.543711 | R10: 11199523 | S10: 322906 | T10: 306859 | U10: 380304 | V10: 4328862 | W10: 11749728 | X10: 341866 | Y10: 6798912.4 | Z10: 381304.62 | AA10: 7180217 | AB10: 1.532836e+10 | AC10: 1.0087576e+10 | AD10: 2.5415936e+10 | AE10: =(AD10-AD9)/AD9 -> -0.023283989
A11: 2032 | B11: 12228417 | C11: 738118 | D11: 606349 | E11: 139464 | F11: =(E11-E10)/E10 -> 0.027820973 | G11: 11.40491 | H11: 65774007 | I11: 4207885 | J11: 69981892 | K11: 1.2396402e+11 | L11: 1.1546135e+11 | M11: 1.2396402e+11 | N11: 2.3942537e+11 | O11: 906450 | P11: 85.019963 | Q11: 89.78444 | R11: 11321967 | S11: 331840 | T11: 318313 | U11: 387898 | V11: 4916554 | W11: 11879536 | X11: 348881 | Y11: 6631510.7 | Z11: 372431.77 | AA11: 7003942.5 | AB11: 1.5095936e+10 | AC11: 9.7749807e+09 | AD11: 2.4870917e+10 | AE11: =(AD11-AD10)/AD10 -> -0.021443994
A12: 2033 | B12: 12366077 | C12: 742479 | D12: 609675 | E12: 144244 | F12: =(E12-E11)/E11 -> 0.034274078 | G12: 11.664491 | H12: 72240844 | I12: 4574547.3 | J12: 76815392 | K12: 1.3882804e+11 | L12: 1.2503178e+11 | M12: 1.3882804e+11 | N12: 2.6385982e+11 | O12: 925675 | P12: 85.43374 | Q12: 90.051202 | R12: 11440402 | S12: 342079 | T12: 331597 | U12: 397496 | V12: 5507477 | W12: 12009883 | X12: 356194 | Y12: 6466837.5 | Z12: 366662.27 | AA12: 6833499.8 | AB12: 1.4864019e+10 | AC12: 9.5704258e+09 | AD12: 2.4434445e+10 | AE12: =(AD12-AD11)/AD11 -> -0.017549499
A13: 2034 | B13: 12504853 | C13: 746867 | D13: 612853 | E13: 147678 | F13: =(E13-E12)/E12 -> 0.023806883 | G13: 11.809655 | H13: 78557182 | I13: 4937097.6 | J13: 83494280 | K13: 1.5349078e+11 | L13: 1.344727e+11 | M13: 1.5349078e+11 | N13: 2.8796348e+11 | O13: 947816 | P13: 85.845868 | Q13: 90.364084 | R13: 11557037 | S13: 351793 | T13: 346538 | U13: 408723 | V13: 6101827 | W13: 12140612 | X13: 364241 | Y13: 6316338.1 | Z13: 362550.26 | AA13: 6678888.3 | AB13: 1.4662739e+10 | AC13: 9.4409245e+09 | AD13: 2.4103664e+10 | AE13: =(AD13-AD12)/AD12 -> -0.013537489
A14: 2035 | B14: 12638959 | C14: 751280 | D14: 621952 | E14: 152175 | F14: =(E14-E13)/E13 -> 0.030451387 | G14: 12.040153 | H14: 84724333 | I14: 5296833.9 | J14: 90021167 | K14: 1.6797941e+11 | L14: 1.4382333e+11 | M14: 1.6797941e+11 | N14: 3.1180274e+11 | O14: 973224 | P14: 86.252142 | Q14: 90.698556 | R14: 11665735 | S14: 362501 | T14: 361912 | U14: 421725 | V14: 6705325 | W14: 12266073 | X14: 372886 | Y14: 6167151.1 | Z14: 359736.31 | AA14: 6526887.4 | AB14: 1.4488634e+10 | AC14: 9.3506267e+09 | AD14: 2.383926e+10 | AE14: =(AD14-AD13)/AD13 -> -0.010969427
... A19: 2040 | B19: 13267159 | C19: 773740 | D19: 695705 | E19: 172404 | F19: =(E19-E18)/E18 -> 0.014272435 | G19: 12.994794 | H19: 1.134351e+08 | I19: 7069256.7 | J19: 1.2050436e+08 | K19: 2.3925084e+11 | L19: 1.8997774e+11 | M19: 2.3925084e+11 | N19: 4.2922858e+11 | O19: 1120015 | P19: 88.161156 | Q19: 92.735637 | R19: 12147144 | S19: 415113 | T19: 444987 | U19: 505970 | V19: 9827498 | W19: 12836808 | X19: 430351 | Y19: 5446391.7 | Z19: 348448.88 | AA19: 5794840.6 | AB19: 1.4045517e+10 | AC19: 9.0866156e+09 | AD19: 2.3132132e+10 | AE19: =(AD19-AD18)/AD18 -> -0.010684169
E20: =(E19-E3)/E3 -> 0.58929921 | O20: =(O19-O3)/O3 -> 0.33647281 | P20: =AVERAGE(P2:P19) -> 84.761558

Sheet Total_Results
B1: 2023 | C1: 2024 | D1: 2025 | E1: 2026 | F1: 2027 | G1: 2028 | H1: 2029 | I1: 2030 | J1: 2031 | K1: 2032 | L1: 2033 | M1: 2034 | N1: 2035 | O1: 2036 | P1: 2037 | Q1: 2038 | R1: 2039 | S1: 2040 | T1: Total
A2: Impact on future dementia burden
A3: Cases avoided
A4: Incident onsets (75% - 50% PD prevalence) | B4: ='75%'!E2-'50%'!E2 -> 0 | C4: ='75%'!E3-'50%'!E3 -> 8742 | D4: ='75%'!E4-'50%'!E4 -> 9831 | E4: ='75%'!E5-'50%'!E5 -> 10267 | F4: ='75%'!E6-'50%'!E6 -> 10341 | G4: ='75%'!E7-'50%'!E7 -> 10007 | H4: ='75%'!E8-'50%'!E8 -> 10681 | I4: ='75%'!E9-'50%'!E9 -> 10404 | J4: ='75%'!E10-'50%'!E10 -> 11452 | K4: ='75%'!E11-'50%'!E11 -> 11021 | L4: ='75%'!E12-'50%'!E12 -> 11515 | M4: ='75%'!E13-'50%'!E13 -> 11882 | N4: ='75%'!E14-'50%'!E14 -> 12037 | O4: ='75%'!E15-'50%'!E15 -> 12720 | P4: ='75%'!E16-'50%'!E16 -> 12391 | Q4: ='75%'!E17-'50%'!E17 -> 12022 | R4: ='75%'!E18-'50%'!E18 -> 12929 | S4: ='75%'!E19-'50%'!E19 -> 12813 | T4: =(SUM('75%'!E3:E19)-SUM('50%'!E3:E19)) -> 191055
A5: Incident onsets (50% - 25% PD prevalence) | B5: ='50%'!E2-'25%'!E2 -> 0 | C5: ='50%'!E3-'25%'!E3 -> 9809 | D5: ='50%'!E4-'25%'!E4 -> 9640 | E5: ='50%'!E5-'25%'!E5 -> 9600 | F5: ='50%'!E6-'25%'!E6 -> 10415 | G5: ='50%'!E7-'25%'!E7 -> 10252 | H5: ='50%'!E8-'25%'!E8 -> 10531 | I5: ='50%'!E9-'25%'!E9 -> 11197 | J5: ='50%'!E10-'25%'!E10 -> 10820 | K5: ='50%'!E11-'25%'!E11 -> 10747 | L5: ='50%'!E12-'25%'!E12 -> 11715 | M5: ='50%'!E13-'25%'!E13 -> 11542 | N5: ='50%'!E14-'25%'!E14 -> 11395 | O5: ='50%'!E15-'25%'!E15 -> 12372 | P5: ='50%'!E16-'25%'!E16 -> 12425 | Q5: ='50%'!E17-'25%'!E17 -> 13347 | R5: ='50%'!E18-'25%'!E18 -> 13342 | S5: ='50%'!E19-'25%'!E19 -> 12629 | T5: =(SUM('50%'!E3:E19)-SUM('25%'!E3:E19)) -> 191778
A6: Prevalence difference
A7: 75% - 50% PD prevalence | B7: ='75%'!O2-'50%'!N2 -> 0 | C7: ='75%'!O3-'50%'!N3 -> 8754 | D7: ='75%'!O4-'50%'!N4 -> 17867 | E7: ='75%'!O5-'50%'!N5 -> 26537 | F7: ='75%'!O6-'50%'!N6 -> 34691 | G7: ='75%'!O7-'50%'!N7 -> 41206 | H7: ='75%'!O8-'50%'!N8 -> 47495 | I7: ='75%'!O9-'50%'!N9 -> 53344 | J7: ='75%'!O10-'50%'!N10 -> 59281 | K7: ='75%'!O11-'50%'!N11 -> 62968 | L7: ='75%'!O12-'50%'!N12 -> 67190 | M7: ='75%'!O13-'50%'!N13 -> 71239 | N7: ='75%'!O14-'50%'!N14 -> 75694 | O7: ='75%'!O15-'50%'!N15 -> 78585 | P7: ='75%'!O16-'50%'!N16 -> 81769 | Q7: ='75%'!O17-'50%'!N17 -> 83661 | R7: ='75%'!O18-'50%'!N18 -> 85051 | S7: ='75%'!O19-'50%'!N19 -> 86564 | T7: =(SUM('75%'!O3:O19)-SUM('50%'!N3:N19)) -> 981896
A8: 50% - 25% PD prevalence | B8: ='50%'!N2-'25%'!N2 -> 0 | C8: ='50%'!N3-'25%'!N3 -> 10223 | D8: ='50%'!N4-'25%'!N4 -> 19353 | E8: ='50%'!N5-'25%'!N5 -> 27491 | F8: ='50%'!N6-'25%'!N6 -> 36800 | G8: ='50%'!N7-'25%'!N7 -> 44878 | H8: ='50%'!N8-'25%'!N8 -> 51540 | I8: ='50%'!N9-'25%'!N9 -> 57232 | J8: ='50%'!N10-'25%'!N10 -> 61116 | K8: ='50%'!N11-'25%'!N11 -> 64916 | L8: ='50%'!N12-'25%'!N12 -> 68694 | M8: ='50%'!N13-'25%'!N13 -> 71347 | N8: ='50%'!N14-'25%'!N14 -> 73462 | O8: ='50%'!N15-'25%'!N15 -> 76911 | P8: ='50%'!N16-'25%'!N16 -> 80661 | Q8: ='50%'!N17-'25%'!N17 -> 83118 | R8: ='50%'!N18-'25%'!N18 -> 86165 | S8: ='50%'!N19-'25%'!N19 -> 86548 | T8: =(SUM('50%'!N3:N19)-SUM('25%'!N3:N19)) -> 1000455
A11: 75% prevalence
A12: Mild | B12: 398969 | C12: 344907 | D12: 317577 | E12: 305083 | F12: 301902 | G12: 302951 | H12: 308143 | I12: 314612 | J12: 322906 | K12: 331840 | L12: 342079 | M12: 351793 | N12: 362501 | O12: 373138 | P12: 387451 | Q12: 396840 | R12: 407100 | S12: 415113 | T12: =SUM(C12:S12) -> 5885936
A13: Moderate | B13: 299115 | C13: 315859 | D13: 309318 | E13: 298605 | F13: 290833 | G13: 288722 | H13: 291135 | I13: 297483 | J13: 306859 | K13: 318313 | L13: 331597 | M13: 346538 | N13: 361912 | O13: 377387 | P13: 396823 | Q13: 412525 | R13: 428385 | S13: 444987 | T13: =SUM(C13:S13) -> 5817281
A14: Severe | B14: 104302 | C14: 194027 | D14: 263902 | E14: 310727 | F14: 338946 | G14: 356124 | H14: 366175 | I14: 373774 | J14: 380304 | K14: 387898 | L14: 397496 | M14: 408723 | N14: 421725 | O14: 436403 | P14: 455815 | Q14: 472706 | R14: 489312 | S14: 505970 | T14: =SUM(C14:S14) -> 6560027
A16: 50% prevalence
A17: Mild | B17: 398969 | C17: 336552 | D17: 302751 | E17: 286033 | F17: 279925 | G17: 280248 | H17: 284269 | I17: 290026 | J17: 296547 | K17: 304872 | L17: 314130 | M17: 323203 | N17: 333498 | O17: 342384 | P17: 356907 | Q17: 366680 | R17: 375933 | S17: 382830 | T17: =SUM(C17:S17) -> 5456788
A18: Moderate | B18: 299115 | C18: 315882 | D18: 306866 | E18: 291594 | F18: 280461 | G18: 274760 | H18: 274061 | I18: 278459 | J18: 285881 | K18: 295432 | L18: 307310 | M18: 320362 | N18: 333130 | O18: 348716 | P18: 365716 | Q18: 381205 | R18: 396356 | S18: 412669 | T18: =SUM(C18:S18) -> 5468860
A19: Severe | B19: 104302 | C19: 193628 | D19: 262942 | E19: 309128 | F19: 334918 | G19: 348830 | H19: 355968 | I19: 359425 | J19: 362852 | K19: 368222 | L19: 374682 | M19: 383140 | N19: 393940 | O19: 406282 | P19: 423738 | Q19: 437451 | R19: 453116 | S19: 468553 | T19: =SUM(C19:S19) -> 6236815
A21: 25% prevalence
A22: Mild | B22: 398969 | C22: 326967 | D22: 287365 | E22: 267465 | F22: 258611 | G22: 257312 | H22: 259847 | I22: 264382 | J22: 270956 | K22: 278852 | L22: 286977 | M22: 295404 | N22: 305018 | O22: 313008 | P22: 326434 | Q22: 334936 | R22: 343572 | S22: 351774 | T22: =SUM(C22:S22) -> 5028880
A23: Moderate | B23: 299115 | C23: 315087 | D23: 302457 | E23: 282885 | F23: 268013 | G23: 258699 | H23: 255954 | I23: 257940 | J23: 263594 | K23: 272499 | L23: 282897 | M23: 294279 | N23: 306981 | O23: 321092 | P23: 336276 | Q23: 350828 | R23: 364326 | S23: 378415 | T23: =SUM(C23:S23) -> 5112222
A24: Severe | B24: 104302 | C24: 193971 | D24: 263420 | E24: 308662 | F24: 331118 | G24: 341452 | H24: 344752 | I24: 345382 | J24: 345790 | K24: 347263 | L24: 351478 | M24: 358388 | N24: 366966 | O24: 377220 | P24: 393139 | Q24: 405178 | R24: 418815 | S24: 433464 | T24: =SUM(C24:S24) -> 5926458
A27: Budget impact and who pays
A28: Net savings professional care
A29: Total NHS costs 75% PD - 50% PD | B29: ='75%'!AB2-'50%'!AA2 -> 0 | C29: ='75%'!AB3-'50%'!AA3 -> 85846095 | D29: ='75%'!AB4-'50%'!AA4 -> 1.775244e+08 | E29: ='75%'!AB5-'50%'!AA5 -> 2.48905e+08 | F29: ='75%'!AB6-'50%'!AA6 -> 3.4230705e+08 | G29: ='75%'!AB7-'50%'!AA7 -> 4.4288169e+08 | H29: ='75%'!AB8-'50%'!AA8 -> 5.3223703e+08 | I29: ='75%'!AB9-'50%'!AA9 -> 6.3957606e+08 | J29: ='75%'!AB10-'50%'!AA10 -> 7.6502031e+08 | K29: ='75%'!AB11-'50%'!AA11 -> 8.4922491e+08 | L29: ='75%'!AB12-'50%'!AA12 -> 9.0244571e+08 | M29: ='75%'!AB13-'50%'!AA13 -> 9.7906669e+08 | N29: ='75%'!AB14-'50%'!AA14 -> 1.0149142e+09 | O29: ='75%'!AB15-'50%'!AA15 -> 1.0738505e+09 | P29: ='75%'!AB16-'50%'!AA16 -> 1.0897892e+09 | Q29: ='75%'!AB17-'50%'!AA17 -> 1.1108338e+09 | R29: ='75%'!AB18-'50%'!AA18 -> 1.1197946e+09 | S29: ='75%'!AB19-'50%'!AA19 -> 1.1110521e+09 | T29: =(SUM('75%'!AB3:AB19)-SUM('50%'!AA3:AA19)) -> 1.2485269e+10
A30: Total NHS costs 50% PD - 25% PD | B30: ='50%'!AA2-'25%'!AA2 -> 0 | C30: ='50%'!AA3-'25%'!AA3 -> 91903073 | D30: ='50%'!AA4-'25%'!AA4 -> 1.5406476e+08 | E30: ='50%'!AA5-'25%'!AA5 -> 2.5478055e+08 | F30: ='50%'!AA6-'25%'!AA6 -> 3.671267e+08 | G30: ='50%'!AA7-'25%'!AA7 -> 5.0922441e+08 | H30: ='50%'!AA8-'25%'!AA8 -> 6.6144928e+08 | I30: ='50%'!AA9-'25%'!AA9 -> 7.7159041e+08 | J30: ='50%'!AA10-'25%'!AA10 -> 8.5169322e+08 | K30: ='50%'!AA11-'25%'!AA11 -> 9.2724205e+08 | L30: ='50%'!AA12-'25%'!AA12 -> 9.8756325e+08 | M30: ='50%'!AA13-'25%'!AA13 -> 1.0041681e+09 | N30: ='50%'!AA14-'25%'!AA14 -> 1.025356e+09 | O30: ='50%'!AA15-'25%'!AA15 -> 1.0329725e+09 | P30: ='50%'!AA16-'25%'!AA16 -> 1.0560266e+09 | Q30: ='50%'!AA17-'25%'!AA17 -> 1.0688641e+09 | R30: ='50%'!AA18-'25%'!AA18 -> 1.0697448e+09 | S30: ='50%'!AA19-'25%'!AA19 -> 1.0569025e+09 | T30: =(SUM('50%'!AA3:AA19)-SUM('25%'!AA3:AA19)) -> 1.2890672e+10
A31: Net savings Informal
A32: Total informal costs 75% PD - 50% PD | B32: ='75%'!AC2-'50%'!AB2 -> 0 | C32: ='75%'!AC3-'50%'!AB3 -> 70410679 | D32: ='75%'!AC4-'50%'!AB4 -> 1.793518e+08 | E32: ='75%'!AC5-'50%'!AB5 -> 3.3316676e+08 | F32: ='75%'!AC6-'50%'!AB6 -> 4.5552788e+08 | G32: ='75%'!AC7-'50%'!AB7 -> 5.5997923e+08 | H32: ='75%'!AC8-'50%'!AB8 -> 6.3430341e+08 | I32: ='75%'!AC9-'50%'!AB9 -> 6.719018e+08 | J32: ='75%'!AC10-'50%'!AB10 -> 7.0432114e+08 | K32: ='75%'!AC11-'50%'!AB11 -> 7.1090022e+08 | L32: ='75%'!AC12-'50%'!AB12 -> 7.2225274e+08 | M32: ='75%'!AC13-'50%'!AB13 -> 7.1630766e+08 | N32: ='75%'!AC14-'50%'!AB14 -> 7.3273242e+08 | O32: ='75%'!AC15-'50%'!AB15 -> 7.2231559e+08 | P32: ='75%'!AC16-'50%'!AB16 -> 7.3671599e+08 | Q32: ='75%'!AC17-'50%'!AB17 -> 7.2284339e+08 | R32: ='75%'!AC18-'50%'!AB18 -> 7.1132553e+08 | S32: ='75%'!AC19-'50%'!AB19 -> 6.9180031e+08 | T32: =(SUM('75%'!AC3:AC19)-SUM('50%'!AB3:AB19)) -> 1.0076157e+10
A33: Total informal costs 50% PD - 25% PD | B33: ='50%'!AB2-'25%'!AB2 -> 0 | C33: ='50%'!AB3-'25%'!AB3 -> 87904733 | D33: ='50%'!AB4-'25%'!AB4 -> 2.4676141e+08 | E33: ='50%'!AB5-'25%'!AB5 -> 3.6237052e+08 | F33: ='50%'!AB6-'25%'!AB6 -> 4.6985801e+08 | G33: ='50%'!AB7-'25%'!AB7 -> 5.7083144e+08 | H33: ='50%'!AB8-'25%'!AB8 -> 6.2544311e+08 | I33: ='50%'!AB9-'25%'!AB9 -> 6.8545178e+08 | J33: ='50%'!AB10-'25%'!AB10 -> 7.2341227e+08 | K33: ='50%'!AB11-'25%'!AB11 -> 7.2042669e+08 | L33: ='50%'!AB12-'25%'!AB12 -> 7.1729034e+08 | M33: ='50%'!AB13-'25%'!AB13 -> 7.3818421e+08 | N33: ='50%'!AB14-'25%'!AB14 -> 7.3082167e+08 | O33: ='50%'!AB15-'25%'!AB15 -> 7.4155133e+08 | P33: ='50%'!AB16-'25%'!AB16 -> 7.4643059e+08 | Q33: ='50%'!AB17-'25%'!AB17 -> 7.4345191e+08 | R33: ='50%'!AB18-'25%'!AB18 -> 7.4233793e+08 | S33: ='50%'!AB19-'25%'!AB19 -> 7.3285025e+08 | T33: =(SUM('50%'!AB3:AB19)-SUM('25%'!AB3:AB19)) -> 1.0385378e+10
A35: Total cost savings
A36: 75% PD - 50% PD | B36: ='75%'!AD2-'50%'!AC2 -> 0 | C36: ='75%'!AD3-'50%'!AC3 -> 1.5625677e+08 | D36: ='75%'!AD4-'50%'!AC4 -> 3.568762e+08 | E36: ='75%'!AD5-'50%'!AC5 -> 5.8207175e+08 | F36: ='75%'!AD6-'50%'!AC6 -> 7.9783493e+08 | G36: ='75%'!AD7-'50%'!AC7 -> 1.0028609e+09 | H36: ='75%'!AD8-'50%'!AC8 -> 1.1665404e+09 | I36: ='75%'!AD9-'50%'!AC9 -> 1.3114779e+09 | J36: ='75%'!AD10-'50%'!AC10 -> 1.4693414e+09 | K36: ='75%'!AD11-'50%'!AC11 -> 1.5601251e+09 | L36: ='75%'!AD12-'50%'!AC12 -> 1.6246984e+09 | M36: ='75%'!AD13-'50%'!AC13 -> 1.6953743e+09 | N36: ='75%'!AD14-'50%'!AC14 -> 1.7476466e+09 | O36: ='75%'!AD15-'50%'!AC15 -> 1.7961661e+09 | P36: ='75%'!AD16-'50%'!AC16 -> 1.8265052e+09 | Q36: ='75%'!AD17-'50%'!AC17 -> 1.8336772e+09 | R36: ='75%'!AD18-'50%'!AC18 -> 1.8311201e+09 | S36: ='75%'!AD19-'50%'!AC19 -> 1.8028524e+09 | T36: =(SUM('75%'!AD3:AD19)-SUM('50%'!AC3:AC19)) -> 2.2561426e+10
A37: 50% PD - 25% PD | B37: ='50%'!AC2-'25%'!AC2 -> 0 | C37: ='50%'!AC3-'25%'!AC3 -> 1.7980781e+08 | D37: ='50%'!AC4-'25%'!AC4 -> 4.0082617e+08 | E37: ='50%'!AC5-'25%'!AC5 -> 6.1715107e+08 | F37: ='50%'!AC6-'25%'!AC6 -> 8.3698471e+08 | G37: ='50%'!AC7-'25%'!AC7 -> 1.0800558e+09 | H37: ='50%'!AC8-'25%'!AC8 -> 1.2868924e+09 | I37: ='50%'!AC9-'25%'!AC9 -> 1.4570422e+09 | J37: ='50%'!AC10-'25%'!AC10 -> 1.5751055e+09 | K37: ='50%'!AC11-'25%'!AC11 -> 1.6476687e+09 | L37: ='50%'!AC12-'25%'!AC12 -> 1.7048536e+09 | M37: ='50%'!AC13-'25%'!AC13 -> 1.7423523e+09 | N37: ='50%'!AC14-'25%'!AC14 -> 1.7561776e+09 | O37: ='50%'!AC15-'25%'!AC15 -> 1.7745239e+09 | P37: ='50%'!AC16-'25%'!AC16 -> 1.8024572e+09 | Q37: ='50%'!AC17-'25%'!AC17 -> 1.812316e+09 | R37: ='50%'!AC18-'25%'!AC18 -> 1.8120827e+09 | S37: ='50%'!AC19-'25%'!AC19 -> 1.7897528e+09 | T37: =(SUM('50%'!AC3:AC19)-SUM('25%'!AC3:AC19)) -> 2.3276051e+10
A39: Cost per case avoided (£ saved per dementia case avoided)
A40: Δtotal costs 75% - 50% / Δ incident onsets | B40: =B36/B4 -> #DIV/0! | C40: =C36/C4 -> 17874.259 | D40: =D36/D4 -> 36301.109 | E40: =E36/E4 -> 56693.46 | F40: =F36/F4 -> 77152.589 | G40: =G36/G4 -> 100215.94 | H40: =H36/H4 -> 109216.41 | I40: =I36/I4 -> 126055.16 | ... T40: =T36/T4 -> 118088.64
A41: Δtotal costs 50% - 25% / Δ incident onsets | B41: =B37/B5 -> #DIV/0! | C41: =C37/C5 -> 18330.901 | D41: =D37/D5 -> 41579.478 | E41: =E37/E5 -> 64286.57 | F41: =F37/F5 -> 80363.39 | G41: =G37/G5 -> 105350.75 | H41: =H37/H5 -> 122200.4 | I41: =I37/I5 -> 130127.91 | ... T41: =T37/T5 -> 121369.76
A44: QALY impact
A45: Patient
A46: Yearly QALYs (75% - 50% PD prevalence) | B46: ='75%'!Y2-'50%'!X2 -> 0 | C46: ='75%'!Y3-'50%'!X3 -> -1044.1711 | D46: ='75%'!Y4-'50%'!X4 -> -982.74272 | E46: ='75%'!Y5-'50%'!X5 -> -2375.783 | F46: ='75%'!Y6-'50%'!X6 -> -3885.5278 | G46: ='75%'!Y7-'50%'!X7 -> -4823.6232 | H46: ='75%'!Y8-'50%'!X8 -> -6851.9342 | I46: ='75%'!Y9-'50%'!X9 -> -9052.0292 | J46: ='75%'!Y10-'50%'!X10 -> -10208.978 | K46: ='75%'!Y11-'50%'!X11 -> -12399.183 | L46: ='75%'!Y12-'50%'!X12 -> -14016.154 | M46: ='75%'!Y13-'50%'!X13 -> -15014.686 | N46: ='75%'!Y14-'50%'!X14 -> -15583.128 | O46: ='75%'!Y15-'50%'!X15 -> -16974.394 | P46: ='75%'!Y16-'50%'!X16 -> -18779.103 | Q46: ='75%'!Y17-'50%'!X17 -> -20535.716 | R46: ='75%'!Y18-'50%'!X18 -> -21529.265 | S46: ='75%'!Y19-'50%'!X19 -> -22738.402 | T46: =(SUM('75%'!Y3:Y19)-SUM('50%'!X3:X19)) -> -196794.82
A47: Yearly QALYs (50% - 25% PD prevalence) | B47: ='50%'!X2-'25%'!X2 -> 0 | C47: ='50%'!X3-'25%'!X3 -> 322.41523 | D47: ='50%'!X4-'25%'!X4 -> -467.36757 | E47: ='50%'!X5-'25%'!X5 -> -1303.249 | F47: ='50%'!X6-'25%'!X6 -> -2062.0701 | G47: ='50%'!X7-'25%'!X7 -> -3367.106 | H47: ='50%'!X8-'25%'!X8 -> -4934.754 | I47: ='50%'!X9-'25%'!X9 -> -6022.9982 | J47: ='50%'!X10-'25%'!X10 -> -8786.6255 | K47: ='50%'!X11-'25%'!X11 -> -10590.264 | L47: ='50%'!X12-'25%'!X12 -> -12696.816 | M47: ='50%'!X13-'25%'!X13 -> -14859.384 | N47: ='50%'!X14-'25%'!X14 -> -17468.828 | O47: ='50%'!X15-'25%'!X15 -> -19285.513 | P47: ='50%'!X16-'25%'!X16 -> -20664.728 | Q47: ='50%'!X17-'25%'!X17 -> -21839.109 | R47: ='50%'!X18-'25%'!X18 -> -23058.453 | S47: ='50%'!X19-'25%'!X19 -> -23585.749 | T47: =(SUM('50%'!X3:X19)-SUM('25%'!X3:X19)) -> -190670.6
A49: Caregiver
A50: Yearly QALYs (75% - 50% PD prevalence) | B50: ='75%'!Z2-'50%'!Y2 -> 0 | C50: ='75%'!Z3-'50%'!Y3 -> 6134.3181 | D50: ='75%'!Z4-'50%'!Y4 -> 12136.92 | E50: ='75%'!Z5-'50%'!Y5 -> 17861.033 | F50: ='75%'!Z6-'50%'!Y6 -> 21808.443 | G50: ='75%'!Z7-'50%'!Y7 -> 24284.108 | H50: ='75%'!Z8-'50%'!Y8 -> 26281.774 | I50: ='75%'!Z9-'50%'!Y9 -> 27217.817 | J50: ='75%'!Z10-'50%'!Y10 -> 28062.576 | K50: ='75%'!Z11-'50%'!Y11 -> 28117.291 | L50: ='75%'!Z12-'50%'!Y12 -> 28408.619 | M50: ='75%'!Z13-'50%'!Y13 -> 28178.871 | N50: ='75%'!Z14-'50%'!Y14 -> 28445.241 | O50: ='75%'!Z15-'50%'!Y15 -> 28316.869 | P50: ='75%'!Z16-'50%'!Y16 -> 28131.411 | Q50: ='75%'!Z17-'50%'!Y17 -> 27523.096 | R50: ='75%'!Z18-'50%'!Y18 -> 27271.713 | S50: ='75%'!Z19-'50%'!Y19 -> 26740.182 | T50: =(SUM('75%'!Z3:Z19)-SUM('50%'!Y3:Y19)) -> 414920.28
A51: Yearly QALYs (50% - 25% PD prevalence) | B51: ='50%'!Y2-'25%'!Y2 -> 0 | C51: ='50%'!Y3-'25%'!Y3 -> 7422.4587 | D51: ='50%'!Y4-'25%'!Y4 -> 14349.116 | E51: ='50%'!Y5-'25%'!Y5 -> 18267.176 | F51: ='50%'!Y6-'25%'!Y6 -> 21865.141 | G51: ='50%'!Y7-'25%'!Y7 -> 24776.442 | H51: ='50%'!Y8-'25%'!Y8 -> 26394.336 | I51: ='50%'!Y9-'25%'!Y9 -> 27849.128 | J51: ='50%'!Y10-'25%'!Y10 -> 28539.806 | K51: ='50%'!Y11-'25%'!Y11 -> 28249.585 | L51: ='50%'!Y12-'25%'!Y12 -> 28127.53 | M51: ='50%'!Y13-'25%'!Y13 -> 28506.757 | N51: ='50%'!Y14-'25%'!Y14 -> 28072.174 | O51: ='50%'!Y15-'25%'!Y15 -> 28451.865 | P51: ='50%'!Y16-'25%'!Y16 -> 28381.31 | Q51: ='50%'!Y17-'25%'!Y17 -> 28455.41 | R51: ='50%'!Y18-'25%'!Y18 -> 28276.577 | S51: ='50%'!Y19-'25%'!Y19 -> 27272.078 | T51: =(SUM('50%'!Y3:Y19)-SUM('25%'!Y3:Y19)) -> 423256.89
...

Sheet PSA
A1: Metric | B1: Mean | C1: Median | D1: Std_Dev | E1: Lower_95_CI | F1: Upper_95_CI | G1: CI_Width | H1: Coefficient_of_variation
A2: 25% Prevalence run
A3: total_costs_nhs | B3: 2.145185e+11 | C3: 2.1389228e+11 | D3: 1.9535549e+10 | E3: 1.7984537e+11 | F3: 2.5334753e+11 | G3: 7.3502163e+10 | H3: =(D3/B3) -> 0.091066963
A4: total_costs_informal | B4: 1.7004085e+11 | C4: 1.7045537e+11 | D4: 1.4160253e+10 | E4: 1.4159991e+11 | F4: 1.9579618e+11 | G4: 5.4196266e+10 | H4: =(D4/B4) -> 0.083275597
A5: total_qalys_patient | B5: 1.1410806e+08 | C5: 1.1376844e+08 | D5: 6588732.2 | E5: 1.0136878e+08 | F5: 1.2662704e+08 | G5: 25258258 | H5: =(D5/B5) -> 0.057741165
A6: total_qalys_caregiver | B6: 6262733.3 | C6: 6236400.6 | D6: 575223.69 | E6: 5160238.9 | F6: 7338859 | G6: 2178620 | H6: =(D6/B6) -> 0.091848665
A7: incident_onsets_total | B7: 10009585 | C7: 10001050 | D7: 189468.1 | E7: 9620585 | F7: 10400602 | G7: 780017.5 | H7: =(D7/B7) -> 0.018928667
A8: total_costs_all | B8: 3.8455935e+11 | C8: 3.8301233e+11 | D8: 2.9073293e+10 | E8: 3.2704732e+11 | F8: 4.4321806e+11 | G8: 1.1617073e+11 | H8: =(D8/B8) -> 0.075601576
A9: total_qalys_combined | B9: 1.2037079e+08 | C9: 1.2008091e+08 | D9: 6575374.5 | E9: 1.0736937e+08 | F9: 1.3292876e+08 | G9: 25559393 | H9: =(D9/B9) -> 0.054625997
A10: stage_mild | B10: 351649.6 | C10: 351000 | D10: 32228.549 | E10: 285585 | F10: 417592.5 | G10: 132007.5 | H10: =(D10/B10) -> 0.091649611
A11: stage_moderate | B11: 3792.998 | C11: 3785.5 | D11: 331.09616 | E11: 3126.225 | F11: 4466 | G11: 1339.775 | H11: =(D11/B11) -> 0.087291414
A12: stage_severe | B12: 433905.2 | C12: 432300 | D12: 36584.285 | E12: 359537.5 | F12: 508452.5 | G12: 148915 | H12: =(D12/B12) -> 0.084314003
A14: 50% Prevalence run
A15: total_costs_nhs | B15: 2.2739772e+11 | C15: 2.2654168e+11 | D15: 2.1350475e+10 | E15: 1.8807688e+11 | F15: 2.720321e+11 | G15: 8.3955227e+10 | H15: =(D15/B15) -> 0.093890455
A16: total_costs_informal | B16: 1.8045612e+11 | C16: 1.8008629e+11 | D16: 1.5487806e+10 | E16: 1.4926974e+11 | F16: 2.10034e+11 | G16: 6.0764261e+10 | H16: =(D16/B16) -> 0.085825884
A17: total_qalys_patient | B17: 1.1391738e+08 | C17: 1.1352727e+08 | D17: 6558448.1 | E17: 1.0126769e+08 | F17: 1.2626195e+08 | G17: 24994257 | H17: =(D17/B17) -> 0.057571971
A18: total_qalys_caregiver | B18: 6689864.1 | C18: 6662100.1 | D18: 639894.4 | E18: 5505712.9 | F18: 7971284.4 | G18: 2465571.4 | H18: =(D18/B18) -> 0.095651331
A19: incident_onsets_total | B19: 10202161 | C19: 10198600 | D19: 213901.02 | E19: 9767847.5 | F19: 10641410 | G19: 873562.5 | H19: =(D19/B19) -> 0.020966246
A20: total_costs_all | B20: 4.0785383e+11 | C20: 4.0741376e+11 | D20: 3.2253586e+10 | E20: 3.4370966e+11 | F20: 4.7326421e+11 | G20: 1.2955454e+11 | H20: =(D20/B20) -> 0.079081238
A21: total_qalys_combined | B21: 1.2060725e+08 | C21: 1.2040363e+08 | D21: 6537754.9 | E21: 1.0767727e+08 | F21: 1.3303662e+08 | G21: 25359353 | H21: =(D21/B21) -> 0.054206983
A22: stage_mild | B22: 384186 | C22: 384200 | D22: 36077.88 | E22: 310742.5 | F22: 459277.5 | G22: 148535 | H22: =(D22/B22) -> 0.093907325
A23: stage_moderate | B23: 4120.048 | C23: 4112.5 | D23: 368.32417 | E23: 3386.375 | F23: 4896.775 | G23: 1510.4 | H23: =(D23/B23) -> 0.089398029
A24: stage_severe | B24: 470336.2 | C24: 470300 | D24: 41487.282 | E24: 384537.5 | F24: 554787.5 | G24: 170250 | H24: =(D24/B24) -> 0.088207715
A26: 75% Prevalence run
A27: total_costs_nhs | B27: 2.4026072e+11 | C27: 2.3981617e+11 | D27: 2.3140532e+10 | E27: 1.9921328e+11 | F27: 2.8725643e+11 | G27: 8.8043146e+10 | H27: =(D27/B27) -> 0.096314254
A28: total_costs_informal | B28: 1.9067384e+11 | C28: 1.9023404e+11 | D28: 1.6990938e+10 | E28: 1.570844e+11 | F28: 2.2310483e+11 | G28: 6.6020435e+10 | H28: =(D28/B28) -> 0.089109962
A29: total_qalys_patient | B29: 1.1373107e+08 | C29: 1.1340985e+08 | D29: 6526612.8 | E29: 1.0116331e+08 | F29: 1.2596936e+08 | G29: 24806050 | H29: =(D29/B29) -> 0.057386365
A30: total_qalys_caregiver | B30: 7109296.4 | C30: 7046723.1 | D30: 703913.64 | E30: 5784311.8 | F30: 8588466.7 | G30: 2804155 | H30: =(D30/B30) -> 0.099013123
A31: incident_onsets_total | B31: 10394192 | C31: 10390400 | D31: 238099.87 | E31: 9918390 | F31: 10909080 | G31: 990690 | H31: =(D31/B31) -> 0.022907011
A32: total_costs_all | B32: 4.3093455e+11 | C32: 4.3105996e+11 | D32: 3.5398919e+10 | E32: 3.5956601e+11 | F32: 5.0404869e+11 | G32: 1.4448268e+11 | H32: =(D32/B32) -> 0.082144535
A33: total_qalys_combined | B33: 1.2084037e+08 | C33: 1.2064859e+08 | D33: 6497177.1 | E33: 1.0794231e+08 | F33: 1.3321806e+08 | G33: 25275757 | H33: =(D33/B33) -> 0.053766611
A34: stage_mild | B34: 415585.8 | C34: 413800 | D34: 39710.714 | E34: 333395 | F34: 503710 | G34: 170315 | H34: =(D34/B34) -> 0.095553588
A35: stage_moderate | B35: 4458.494 | C35: 4456.5 | D35: 412.78283 | E35: 3639.9 | F35: 5366.3 | G35: 1726.4 | H35: =(D35/B35) -> 0.092583466
A36: stage_severe | B36: 507296 | C36: 508950 | D36: 46151.594 | E36: 415565 | F36: 606232.5 | G36: 190667.5 | H36: =(D36/B36) -> 0.09097567

Sheet OneWay_Sensitivity
A1: total_costs_nhs | B1: total_costs_informal | C1: total_qalys_patient | D1: total_qalys_caregiver | E1: incident_onsets_total | F1: total_deaths | G1: total_entrants | H1: total_costs_all | I1: total_qalys_combined | J1: stage_mild | K1: stage_moderate | L1: stage_severe | M1: parameter | N1: value_type | O1: replicate
A2: 2.3938237e+11 | B2: 1.9180576e+11 | C2: 1.1340275e+08 | D2: 7128955.4 | E2: 2467800 | F2: 10632500 | G2: 13253300 | H2: 4.3118813e+11 | I2: 1.2053171e+08 | J2: 411700 | K2: 4503 | L2: 509500 | M2: baseline | N2: baseline | O2: 0
A3: 2.2112773e+11 | B3: 1.7801714e+11 | C3: 1.1009559e+08 | D3: 6617948.1 | E3: 2312500 | F3: 11234200 | G3: 13253300 | H3: 3.9914487e+11 | I3: 1.1671354e+08 | J3: 380300 | K3: 4280 | L3: 468700 | M3: baseline | N3: baseline | O3: 1
A4: 2.0191272e+11 | B4: 1.6290174e+11 | C4: 1.0598133e+08 | D4: 6098326.2 | E4: 2147200 | F4: 11876100 | G4: 13253300 | H4: 3.6481446e+11 | I4: 1.1207965e+08 | J4: 340500 | K4: 4072 | L4: 449200 | M4: baseline | N4: baseline | O4: 2
A5: 1.7676014e+11 | B5: 1.4415929e+11 | C5: 1.0028788e+08 | D5: 5399696.1 | E5: 1932200 | F5: 12640500 | G5: 13253300 | H5: 3.2091944e+11 | I5: 1.0568758e+08 | J5: 308500 | K5: 3811 | L5: 404300 | M5: baseline | N5: baseline | O5: 3
A6: 1.6399751e+11 | B6: 1.3398086e+11 | C6: 96138762 | D6: 5025022.4 | E6: 1792600 | F6: 13265200 | G6: 13253300 | H6: 2.9797838e+11 | I6: 1.0116378e+08 | J6: 278700 | K6: 3591 | L6: 376600 | M6: baseline | N6: baseline | O6: 4
A7: 1.5299392e+11 | B7: 1.2454156e+11 | C7: 92732123 | D7: 4673580.3 | E7: 1685700 | F7: 13807900 | G7: 13253300 | H7: 2.7753548e+11 | I7: 97405704 | J7: 253900 | K7: 3574 | L7: 347100 | M7: baseline | N7: baseline | O7: 5
A8: 1.4491837e+11 | B8: 1.1992573e+11 | C8: 90412784 | D8: 4492505.6 | E8: 1612200 | F8: 14169600 | G8: 13253300 | H8: 2.6484409e+11 | I8: 94905290 | J8: 238200 | K8: 3362 | L8: 343900 | M8: baseline | N8: baseline | O8: 6
A9: 1.3645034e+11 | B9: 1.1215235e+11 | C9: 87794383 | D9: 4210311.6 | E9: 1535000 | F9: 14560400 | G9: 13253300 | H9: 2.4860269e+11 | I9: 92004695 | J9: 227000 | K9: 3282 | L9: 328300 | M9: baseline | N9: baseline | O9: 7
A10: 1.2800582e+11 | B10: 1.0804566e+11 | C10: 85689870 | D10: 4091460.6 | E10: 1479900 | F10: 14912800 | G10: 13253300 | H10: 2.3605148e+11 | I10: 89781331 | J10: 220800 | K10: 3203 | L10: 317600 | M10: baseline | N10: baseline | O10: 8
A11: 1.2065744e+11 | B11: 1.0201467e+11 | C11: 83242831 | D11: 3857868.1 | E11: 1415200 | F11: 15350300 | G11: 13253300 | H11: 2.2267211e+11 | I11: 87100699 | J11: 209800 | K11: 2978 | L11: 309700 | M11: baseline | N11: baseline | O11: 9
A12: 1.0873509e+11 | B12: 9.3596507e+10 | C12: 81598832 | D12: 3511228.1 | E12: 1274800 | F12: 15640300 | G12: 13253300 | H12: 2.023316e+11 | I12: 85110060 | J12: 182200 | K12: 2786 | L12: 287200 | M12: onset_rr | N12: low | O12: 0
A13: 1.09423e+11 | B13: 9.0783928e+10 | C13: 79394405 | D13: 3415818 | E13: 1243300 | F13: 15906800 | G13: 13253300 | H13: 2.0020693e+11 | I13: 82810223 | J13: 171800 | K13: 2886 | L13: 285500 | M13: onset_rr | N13: low | O13: 1
... A31: 8.394676e+10 | B31: 7.2899586e+10 | C31: 66876322 | D31: 2826850.1 | E31: 1098700 | F31: 17960700 | G31: 13253300 | H31: 1.5684635e+11 | I31: 69703172 | J31: 133200 | K31: 2757 | L31: 250900 | M31: onset_rr | N31: high | O31: 9
A35: Parameter | B35: Metric | C35: Low_Value | D35: High_Value | E35: Swing | F35: Swing_Pct
A36: onset_rr | B36: total_costs_all | C36: 1.6991446e+11 | D36: 1.9076927e+11 | E36: 2.0854807e+10 | F36: 12.273709
A37: onset_rr | B37: total_qalys_combined | C37: 76879434 | D37: 77126742 | E37: 247308.38 | F37: 0.32168341
A38: onset_rr | B38: incident_onsets_total | C38: 1100770 | D38: 1284280 | E38: 183510 | F38: 16.671058
